---
title: Try... Catch... Abschließend-Anweisung
description: Erfahren Sie, wie Sie die Ausnahmebehandlung mit Visual Basic try/catch/letzenanweisungen verwenden.
ms.date: 12/07/2018
f1_keywords:
- vb.Try...Catch...Finally
- vb.when
- vb.Finally
- vb.Catch
- vb.Try
helpviewer_keywords:
- Try...Catch...Finally statements
- Try statement [Visual Basic]
- try-catch exception handling, Try...Catch...Finally statements
- error handling, while running code
- Try statement [Visual Basic], Try...Catch...Finally
- Finally keyword [Visual Basic], Try...Catch...Finally
- Catch statement [Visual Basic]
- When keyword [Visual Basic]
- Visual Basic code, handling errors while running
- structured exception handling, Try...Catch...Finally statements
ms.assetid: d6488026-ccb3-42b8-a810-0d97b9d6472b
ms.openlocfilehash: 22f1611786a3da512632b5b547b7ef141c8f65c6
ms.sourcegitcommit: f8c270376ed905f6a8896ce0fe25b4f4b38ff498
ms.translationtype: MT
ms.contentlocale: de-DE
ms.lasthandoff: 06/04/2020
ms.locfileid: "84391767"
---
# <a name="trycatchfinally-statement-visual-basic"></a><span data-ttu-id="9547a-103">Try...Catch...Finally-Anweisung (Visual Basic)</span><span class="sxs-lookup"><span data-stu-id="9547a-103">Try...Catch...Finally Statement (Visual Basic)</span></span>

<span data-ttu-id="9547a-104">Bietet eine Möglichkeit, einige oder alle möglichen Fehler zu behandeln, die in einem bestimmten Codeblock auftreten können, während Code weiterhin ausgeführt wird.</span><span class="sxs-lookup"><span data-stu-id="9547a-104">Provides a way to handle some or all possible errors that may occur in a given block of code, while still running code.</span></span>

## <a name="syntax"></a><span data-ttu-id="9547a-105">Syntax</span><span class="sxs-lookup"><span data-stu-id="9547a-105">Syntax</span></span>

```vb
Try
    [ tryStatements ]
    [ Exit Try ]
[ Catch [ exception [ As type ] ] [ When expression ]
    [ catchStatements ]
    [ Exit Try ] ]
[ Catch ... ]
[ Finally
    [ finallyStatements ] ]
End Try
```

## <a name="parts"></a><span data-ttu-id="9547a-106">Bestandteile</span><span class="sxs-lookup"><span data-stu-id="9547a-106">Parts</span></span>

|<span data-ttu-id="9547a-107">Begriff</span><span class="sxs-lookup"><span data-stu-id="9547a-107">Term</span></span>|<span data-ttu-id="9547a-108">Definition</span><span class="sxs-lookup"><span data-stu-id="9547a-108">Definition</span></span>|
|---|---|
|`tryStatements`|<span data-ttu-id="9547a-109">Dies ist optional.</span><span class="sxs-lookup"><span data-stu-id="9547a-109">Optional.</span></span> <span data-ttu-id="9547a-110">Anweisung (en), in der ein Fehler auftreten kann.</span><span class="sxs-lookup"><span data-stu-id="9547a-110">Statement(s) where an error can occur.</span></span> <span data-ttu-id="9547a-111">Kann eine Verbundanweisung sein.</span><span class="sxs-lookup"><span data-stu-id="9547a-111">Can be a compound statement.</span></span>|
|`Catch`|<span data-ttu-id="9547a-112">Optional.</span><span class="sxs-lookup"><span data-stu-id="9547a-112">Optional.</span></span> <span data-ttu-id="9547a-113">Mehrere `Catch` Blöcke sind zulässig.</span><span class="sxs-lookup"><span data-stu-id="9547a-113">Multiple `Catch` blocks permitted.</span></span> <span data-ttu-id="9547a-114">Wenn bei der Verarbeitung des-Blocks eine Ausnahme auftritt `Try` , wird jede- `Catch` Anweisung in der Text Reihenfolge untersucht, um zu bestimmen, ob die Ausnahme behandelt wird, wobei `exception` die ausgelöste Ausnahme darstellt.</span><span class="sxs-lookup"><span data-stu-id="9547a-114">If an exception occurs when processing the `Try` block, each `Catch` statement is examined in textual order to determine whether it handles the exception, with `exception` representing the exception that has been thrown.</span></span>|
|`exception`|<span data-ttu-id="9547a-115">Optional.</span><span class="sxs-lookup"><span data-stu-id="9547a-115">Optional.</span></span> <span data-ttu-id="9547a-116">Ein beliebiger Variablenname.</span><span class="sxs-lookup"><span data-stu-id="9547a-116">Any variable name.</span></span> <span data-ttu-id="9547a-117">Der Anfangswert von `exception` ist der Wert des ausgelösten Fehlers.</span><span class="sxs-lookup"><span data-stu-id="9547a-117">The initial value of `exception` is the value of the thrown error.</span></span> <span data-ttu-id="9547a-118">Wird mit verwendet `Catch` , um den aufgefangenen Fehler anzugeben.</span><span class="sxs-lookup"><span data-stu-id="9547a-118">Used with `Catch` to specify the error caught.</span></span> <span data-ttu-id="9547a-119">Wenn Sie nicht vorhanden ist, fängt die- `Catch` Anweisung jede Ausnahme ab.</span><span class="sxs-lookup"><span data-stu-id="9547a-119">If omitted, the `Catch` statement catches any exception.</span></span>|
|`type`|<span data-ttu-id="9547a-120">Optional.</span><span class="sxs-lookup"><span data-stu-id="9547a-120">Optional.</span></span> <span data-ttu-id="9547a-121">Gibt den Typ des Klassen Filters an.</span><span class="sxs-lookup"><span data-stu-id="9547a-121">Specifies the type of class filter.</span></span> <span data-ttu-id="9547a-122">Wenn der Wert von vom `exception` Typ ist, der von `type` oder einem abgeleiteten Typ angegeben wird, wird der Bezeichner an das Ausnahme Objekt gebunden.</span><span class="sxs-lookup"><span data-stu-id="9547a-122">If the value of `exception` is of the type specified by `type` or of a derived type, the identifier becomes bound to the exception object.</span></span>|
|`When`|<span data-ttu-id="9547a-123">Optional.</span><span class="sxs-lookup"><span data-stu-id="9547a-123">Optional.</span></span> <span data-ttu-id="9547a-124">Eine- `Catch` Anweisung mit einer- `When` Klausel fängt Ausnahmen nur ab, wenn als `expression` ausgewertet wird `True` .</span><span class="sxs-lookup"><span data-stu-id="9547a-124">A `Catch` statement with a `When` clause catches exceptions only when `expression` evaluates to `True`.</span></span> <span data-ttu-id="9547a-125">Eine `When` -Klausel wird erst angewendet, nachdem der Typ der Ausnahme überprüft wurde, und `expression` verweist möglicherweise auf den Bezeichner, der die Ausnahme darstellt.</span><span class="sxs-lookup"><span data-stu-id="9547a-125">A `When` clause is applied only after checking the type of the exception, and `expression` may refer to the identifier representing the exception.</span></span>|
|`expression`|<span data-ttu-id="9547a-126">Optional.</span><span class="sxs-lookup"><span data-stu-id="9547a-126">Optional.</span></span> <span data-ttu-id="9547a-127">Muss implizit in konvertierbar sein `Boolean` .</span><span class="sxs-lookup"><span data-stu-id="9547a-127">Must be implicitly convertible to `Boolean`.</span></span> <span data-ttu-id="9547a-128">Jeder Ausdruck, der einen generischen Filter beschreibt.</span><span class="sxs-lookup"><span data-stu-id="9547a-128">Any expression that describes a generic filter.</span></span> <span data-ttu-id="9547a-129">Wird normalerweise verwendet, um nach Fehlernummer zu filtern.</span><span class="sxs-lookup"><span data-stu-id="9547a-129">Typically used to filter by error number.</span></span> <span data-ttu-id="9547a-130">Wird mit `When` dem-Schlüsselwort verwendet, um Umstände anzugeben, unter denen der Fehler abgefangen wird.</span><span class="sxs-lookup"><span data-stu-id="9547a-130">Used with `When` keyword to specify circumstances under which the error is caught.</span></span>|
|`catchStatements`|<span data-ttu-id="9547a-131">Optional.</span><span class="sxs-lookup"><span data-stu-id="9547a-131">Optional.</span></span> <span data-ttu-id="9547a-132">Anweisung (en) zum Behandeln von Fehlern, die im zugeordneten- `Try` Block auftreten.</span><span class="sxs-lookup"><span data-stu-id="9547a-132">Statement(s) to handle errors that occur in the associated `Try` block.</span></span> <span data-ttu-id="9547a-133">Kann eine Verbundanweisung sein.</span><span class="sxs-lookup"><span data-stu-id="9547a-133">Can be a compound statement.</span></span>|
|`Exit Try`|<span data-ttu-id="9547a-134">Optional.</span><span class="sxs-lookup"><span data-stu-id="9547a-134">Optional.</span></span> <span data-ttu-id="9547a-135">Ein Schlüsselwort, das die `Try...Catch...Finally` Struktur unterbricht.</span><span class="sxs-lookup"><span data-stu-id="9547a-135">Keyword that breaks out of the `Try...Catch...Finally` structure.</span></span> <span data-ttu-id="9547a-136">Die Ausführung wird mit dem Code direkt nach der-Anweisung fortgesetzt `End Try` .</span><span class="sxs-lookup"><span data-stu-id="9547a-136">Execution resumes with the code immediately following the `End Try` statement.</span></span> <span data-ttu-id="9547a-137">Die- `Finally` Anweisung wird weiterhin ausgeführt.</span><span class="sxs-lookup"><span data-stu-id="9547a-137">The `Finally` statement will still be executed.</span></span> <span data-ttu-id="9547a-138">In-Blöcken nicht zulässig `Finally` .</span><span class="sxs-lookup"><span data-stu-id="9547a-138">Not allowed in `Finally` blocks.</span></span>|
|`Finally`|<span data-ttu-id="9547a-139">Optional.</span><span class="sxs-lookup"><span data-stu-id="9547a-139">Optional.</span></span> <span data-ttu-id="9547a-140">Ein- `Finally` Block wird immer ausgeführt, wenn die Ausführung einen beliebigen Teil der `Try...Catch` Anweisung verlässt.</span><span class="sxs-lookup"><span data-stu-id="9547a-140">A `Finally` block is always executed when execution leaves any part of the `Try...Catch` statement.</span></span>|
|`finallyStatements`|<span data-ttu-id="9547a-141">Optional.</span><span class="sxs-lookup"><span data-stu-id="9547a-141">Optional.</span></span> <span data-ttu-id="9547a-142">Anweisung (en), die ausgeführt wird, nachdem alle anderen Fehler verarbeitet wurden.</span><span class="sxs-lookup"><span data-stu-id="9547a-142">Statement(s) that are executed after all other error processing has occurred.</span></span>|
|`End Try`|<span data-ttu-id="9547a-143">Beendet die- `Try...Catch...Finally` Struktur.</span><span class="sxs-lookup"><span data-stu-id="9547a-143">Terminates the `Try...Catch...Finally` structure.</span></span>|

## <a name="remarks"></a><span data-ttu-id="9547a-144">Bemerkungen</span><span class="sxs-lookup"><span data-stu-id="9547a-144">Remarks</span></span>

<span data-ttu-id="9547a-145">Wenn Sie davon ausgehen, dass eine bestimmte Ausnahme während eines bestimmten Code Abschnitts auftreten kann, platzieren Sie den Code in einem `Try` -Block, und verwenden Sie einen- `Catch` Block, um die Steuerung beizubehalten und die Ausnahme zu behandeln, wenn Sie auftritt.</span><span class="sxs-lookup"><span data-stu-id="9547a-145">If you expect that a particular exception might occur during a particular section of code, put the code in a `Try` block and use a `Catch` block to retain control and handle the exception if it occurs.</span></span>

<span data-ttu-id="9547a-146">Eine- `Try…Catch` Anweisung besteht aus einem- `Try` Block, gefolgt von einer oder mehreren- `Catch` Klauseln, die Handler für verschiedene Ausnahmen angeben.</span><span class="sxs-lookup"><span data-stu-id="9547a-146">A `Try…Catch` statement consists of a `Try` block followed by one or more `Catch` clauses, which specify handlers for various exceptions.</span></span> <span data-ttu-id="9547a-147">Wenn eine Ausnahme in einem-Block ausgelöst wird `Try` , sucht Visual Basic nach der `Catch` Anweisung, die die Ausnahme behandelt.</span><span class="sxs-lookup"><span data-stu-id="9547a-147">When an exception is thrown in a `Try` block, Visual Basic looks for the `Catch` statement that handles the exception.</span></span> <span data-ttu-id="9547a-148">Wenn keine übereinstimmende `Catch` Anweisung gefunden wird, überprüft Visual Basic die Methode, die die aktuelle Methode aufgerufen hat, usw.</span><span class="sxs-lookup"><span data-stu-id="9547a-148">If a matching `Catch` statement is not found, Visual Basic examines the method that called the current method, and so on up the call stack.</span></span> <span data-ttu-id="9547a-149">Wenn kein- `Catch` Block gefunden wird, zeigt Visual Basic eine unbehandelte Ausnahme Meldung an den Benutzer an und beendet die Ausführung des Programms.</span><span class="sxs-lookup"><span data-stu-id="9547a-149">If no `Catch` block is found, Visual Basic displays an unhandled exception message to the user and stops execution of the program.</span></span>

<span data-ttu-id="9547a-150">Sie können mehr als eine `Catch` Anweisung in einer- `Try…Catch` Anweisung verwenden.</span><span class="sxs-lookup"><span data-stu-id="9547a-150">You can use more than one `Catch` statement in a `Try…Catch` statement.</span></span> <span data-ttu-id="9547a-151">Wenn Sie dies tun, ist die Reihenfolge der `Catch` Klauseln von Bedeutung, da Sie in der richtigen Reihenfolge untersucht werden.</span><span class="sxs-lookup"><span data-stu-id="9547a-151">If you do this, the order of the `Catch` clauses is significant because they are examined in order.</span></span> <span data-ttu-id="9547a-152">Fangen Sie spezifischere Ausnahmen vor den weniger spezifischen ab.</span><span class="sxs-lookup"><span data-stu-id="9547a-152">Catch the more specific exceptions before the less specific ones.</span></span>

<span data-ttu-id="9547a-153">Die folgenden `Catch` Anweisungs Bedingungen sind der spezifischere und fangen alle Ausnahmen ab, die von der-Klasse abgeleitet werden <xref:System.Exception> .</span><span class="sxs-lookup"><span data-stu-id="9547a-153">The following `Catch` statement conditions are the least specific, and will catch all exceptions that derive from the <xref:System.Exception> class.</span></span> <span data-ttu-id="9547a-154">Normalerweise sollten Sie eine dieser Variationen als letzten `Catch` Block in der Struktur verwenden `Try...Catch...Finally` , nachdem Sie alle erwarteten Ausnahmen abgefangen haben.</span><span class="sxs-lookup"><span data-stu-id="9547a-154">You should ordinarily use one of these variations as the last `Catch` block in the `Try...Catch...Finally` structure, after catching all the specific exceptions you expect.</span></span> <span data-ttu-id="9547a-155">Die Ablauf Steuerung kann niemals einen `Catch` Block erreichen, der einer dieser Variationen folgt.</span><span class="sxs-lookup"><span data-stu-id="9547a-155">Control flow can never reach a `Catch` block that follows either of these variations.</span></span>

- <span data-ttu-id="9547a-156">Ist z. b. `type` `Exception` :`Catch ex As Exception`</span><span class="sxs-lookup"><span data-stu-id="9547a-156">The `type` is `Exception`, for example: `Catch ex As Exception`</span></span>

- <span data-ttu-id="9547a-157">Die-Anweisung hat keine `exception` Variable, z. b.:`Catch`</span><span class="sxs-lookup"><span data-stu-id="9547a-157">The statement has no `exception` variable, for example: `Catch`</span></span>

<span data-ttu-id="9547a-158">Wenn eine- `Try…Catch…Finally` Anweisung in einem anderen Block eingebettet ist `Try` , untersucht Visual Basic zuerst jede `Catch` Anweisung im innersten `Try` Block.</span><span class="sxs-lookup"><span data-stu-id="9547a-158">When a `Try…Catch…Finally` statement is nested in another `Try` block, Visual Basic first examines each `Catch` statement in the innermost `Try` block.</span></span> <span data-ttu-id="9547a-159">Wenn keine übereinstimmende `Catch` Anweisung gefunden wird, geht die Suche mit den `Catch` Anweisungen des äußeren `Try…Catch…Finally` Blocks fort.</span><span class="sxs-lookup"><span data-stu-id="9547a-159">If no matching `Catch` statement is found, the search proceeds to the `Catch` statements of the outer `Try…Catch…Finally` block.</span></span>

<span data-ttu-id="9547a-160">Lokale Variablen aus einem- `Try` Block sind in einem-Block nicht verfügbar, `Catch` da es sich um separate Blöcke handelt.</span><span class="sxs-lookup"><span data-stu-id="9547a-160">Local variables from a `Try` block are not available in a `Catch` block because they are separate blocks.</span></span> <span data-ttu-id="9547a-161">Wenn Sie eine Variable in mehr als einem Block verwenden möchten, deklarieren Sie die Variable außerhalb der `Try...Catch...Finally` Struktur.</span><span class="sxs-lookup"><span data-stu-id="9547a-161">If you want to use a variable in more than one block, declare the variable outside the `Try...Catch...Finally` structure.</span></span>

> [!TIP]
> <span data-ttu-id="9547a-162">Die- `Try…Catch…Finally` Anweisung ist als IntelliSense-Code Ausschnitt verfügbar.</span><span class="sxs-lookup"><span data-stu-id="9547a-162">The `Try…Catch…Finally` statement is available as an IntelliSense code snippet.</span></span> <span data-ttu-id="9547a-163">Erweitern Sie im Code Ausschnitt-Manager **Code Patterns-if, for each, try catch, Property, usw**., und dann **Fehlerbehandlung (Ausnahmen)**.</span><span class="sxs-lookup"><span data-stu-id="9547a-163">In the Code Snippets Manager, expand **Code Patterns - If, For Each, Try Catch, Property, etc**, and then **Error Handling (Exceptions)**.</span></span> <span data-ttu-id="9547a-164">Weitere Informationen finden Sie unter [Codeausschnitte](/visualstudio/ide/code-snippets).</span><span class="sxs-lookup"><span data-stu-id="9547a-164">For more information, see [Code Snippets](/visualstudio/ide/code-snippets).</span></span>

## <a name="finally-block"></a><span data-ttu-id="9547a-165">Schließlich blockieren</span><span class="sxs-lookup"><span data-stu-id="9547a-165">Finally block</span></span>

<span data-ttu-id="9547a-166">Wenn Sie über eine oder mehrere-Anweisungen verfügen, die vor dem Beenden der- `Try` Struktur ausgeführt werden müssen, verwenden Sie einen- `Finally` Block.</span><span class="sxs-lookup"><span data-stu-id="9547a-166">If you have one or more statements that must run before you exit the `Try` structure, use a `Finally` block.</span></span> <span data-ttu-id="9547a-167">Die Steuerung wird an den Block weitergeleitet, `Finally` kurz bevor Sie aus der `Try…Catch` Struktur übergeht.</span><span class="sxs-lookup"><span data-stu-id="9547a-167">Control passes to the `Finally` block just before it passes out of the `Try…Catch` structure.</span></span> <span data-ttu-id="9547a-168">Dies gilt auch, wenn eine Ausnahme an einer beliebigen Stelle innerhalb der `Try` Struktur auftritt.</span><span class="sxs-lookup"><span data-stu-id="9547a-168">This is true even if an exception occurs anywhere inside the `Try` structure.</span></span>

<span data-ttu-id="9547a-169">Ein- `Finally` Block eignet sich zum Ausführen von Code, der ausgeführt werden muss, auch wenn eine Ausnahme vorliegt.</span><span class="sxs-lookup"><span data-stu-id="9547a-169">A `Finally` block is useful for running any code that must execute even if there is an exception.</span></span> <span data-ttu-id="9547a-170">Das Steuerelement wird `Finally` unabhängig davon, wie der Block beendet wird, an den Block übertragen `Try...Catch` .</span><span class="sxs-lookup"><span data-stu-id="9547a-170">Control is passed to the `Finally` block regardless of how the `Try...Catch` block exits.</span></span>

<span data-ttu-id="9547a-171">Der Code in einem- `Finally` Block wird auch dann ausgeführt, wenn der Code eine- `Return` Anweisung in einem- `Try` oder-Block findet `Catch` .</span><span class="sxs-lookup"><span data-stu-id="9547a-171">The code in a `Finally` block runs even if your code encounters a `Return` statement in a `Try` or `Catch` block.</span></span> <span data-ttu-id="9547a-172">Das-Steuerelement wird `Try` in den folgenden Fällen nicht von einem-oder- `Catch` Block an den entsprechenden- `Finally` Block übergeben:</span><span class="sxs-lookup"><span data-stu-id="9547a-172">Control does not pass from a `Try` or `Catch` block to the corresponding `Finally` block in the following cases:</span></span>

- <span data-ttu-id="9547a-173">Eine [End-Anweisung](end-statement.md) ist im- `Try` oder- `Catch` Block aufgetreten.</span><span class="sxs-lookup"><span data-stu-id="9547a-173">An [End Statement](end-statement.md) is encountered in the `Try` or `Catch` block.</span></span>

- <span data-ttu-id="9547a-174">Eine <xref:System.StackOverflowException> wird im- `Try` oder- `Catch` Block ausgelöst.</span><span class="sxs-lookup"><span data-stu-id="9547a-174">A <xref:System.StackOverflowException> is thrown in the `Try` or `Catch` block.</span></span>

<span data-ttu-id="9547a-175">Die explizite Übertragung der Ausführung in einen-Block ist ungültig `Finally` .</span><span class="sxs-lookup"><span data-stu-id="9547a-175">It is not valid to explicitly transfer execution into a `Finally` block.</span></span> <span data-ttu-id="9547a-176">Das übertragen der Ausführung aus einem `Finally` Block ist ungültig, außer durch eine Ausnahme.</span><span class="sxs-lookup"><span data-stu-id="9547a-176">Transferring execution out of a `Finally` block is not valid, except through an exception.</span></span>

<span data-ttu-id="9547a-177">Wenn eine `Try` Anweisung nicht mindestens einen `Catch` Block enthält, muss Sie einen-Block enthalten `Finally` .</span><span class="sxs-lookup"><span data-stu-id="9547a-177">If a `Try` statement does not contain at least one `Catch` block, it must contain a `Finally` block.</span></span>

> [!TIP]
> <span data-ttu-id="9547a-178">Wenn Sie keine bestimmten Ausnahmen abfangen müssen, verhält sich die `Using` -Anweisung wie ein `Try…Finally` -Block, und garantiert die Freigabe der Ressourcen, unabhängig davon, wie Sie den Block beenden.</span><span class="sxs-lookup"><span data-stu-id="9547a-178">If you do not have to catch specific exceptions, the `Using` statement behaves like a `Try…Finally` block, and guarantees disposal of the resources, regardless of how you exit the block.</span></span> <span data-ttu-id="9547a-179">Dies gilt auch bei einer nicht behandelten Ausnahme.</span><span class="sxs-lookup"><span data-stu-id="9547a-179">This is true even with an unhandled exception.</span></span> <span data-ttu-id="9547a-180">Weitere Informationen finden Sie unter [using-Anweisung](using-statement.md).</span><span class="sxs-lookup"><span data-stu-id="9547a-180">For more information, see [Using Statement](using-statement.md).</span></span>

## <a name="exception-argument"></a><span data-ttu-id="9547a-181">Exception-Argument</span><span class="sxs-lookup"><span data-stu-id="9547a-181">Exception argument</span></span>

<span data-ttu-id="9547a-182">Das `Catch` Block `exception` Argument ist eine Instanz der- <xref:System.Exception> Klasse oder eine Klasse, die von der-Klasse abgeleitet wird `Exception` .</span><span class="sxs-lookup"><span data-stu-id="9547a-182">The `Catch` block `exception` argument is an instance of the <xref:System.Exception> class or a class that derives from the `Exception` class.</span></span> <span data-ttu-id="9547a-183">Die- `Exception` Klasseninstanz entspricht dem Fehler, der im- `Try` Block aufgetreten ist.</span><span class="sxs-lookup"><span data-stu-id="9547a-183">The `Exception` class instance corresponds to the error that occurred in the `Try` block.</span></span>

<span data-ttu-id="9547a-184">Die Eigenschaften des- `Exception` Objekts helfen dabei, die Ursache und den Speicherort einer Ausnahme zu ermitteln.</span><span class="sxs-lookup"><span data-stu-id="9547a-184">The properties of the `Exception` object help to identify the cause and location of an exception.</span></span> <span data-ttu-id="9547a-185">Beispielsweise werden in der- <xref:System.Exception.StackTrace%2A> Eigenschaft die aufgerufenen Methoden aufgelistet, die zur Ausnahme geführt haben. Dadurch können Sie ermitteln, wo der Fehler im Code aufgetreten ist.</span><span class="sxs-lookup"><span data-stu-id="9547a-185">For example, the <xref:System.Exception.StackTrace%2A> property lists the called methods that led to the exception, helping you find where the error occurred in the code.</span></span> <span data-ttu-id="9547a-186"><xref:System.Exception.Message%2A>gibt eine Meldung zurück, in der die Ausnahme beschrieben wird.</span><span class="sxs-lookup"><span data-stu-id="9547a-186"><xref:System.Exception.Message%2A> returns a message that describes the exception.</span></span> <span data-ttu-id="9547a-187"><xref:System.Exception.HelpLink%2A>Gibt einen Link zu einer zugeordneten Hilfedatei zurück.</span><span class="sxs-lookup"><span data-stu-id="9547a-187"><xref:System.Exception.HelpLink%2A> returns a link to an associated Help file.</span></span> <span data-ttu-id="9547a-188"><xref:System.Exception.InnerException%2A>Gibt das- `Exception` Objekt zurück, das die aktuelle Ausnahme verursacht hat, oder gibt zurück, `Nothing` Wenn kein ursprüngliches vorhanden ist `Exception` .</span><span class="sxs-lookup"><span data-stu-id="9547a-188"><xref:System.Exception.InnerException%2A> returns the `Exception` object that caused the current exception, or it returns `Nothing` if there is no original `Exception`.</span></span>

## <a name="considerations-when-using-a-trycatch-statement"></a><span data-ttu-id="9547a-189">Überlegungen bei der Verwendung von Try... Catch-Anweisung</span><span class="sxs-lookup"><span data-stu-id="9547a-189">Considerations when using a Try…Catch statement</span></span>

<span data-ttu-id="9547a-190">Verwenden Sie eine- `Try…Catch` Anweisung, um das Vorkommen von ungewöhnlichen oder unerwarteten Programm Ereignissen zu signalisieren.</span><span class="sxs-lookup"><span data-stu-id="9547a-190">Use a `Try…Catch` statement only to signal the occurrence of unusual or unanticipated program events.</span></span> <span data-ttu-id="9547a-191">Hierfür sind die folgenden Gründe zu berücksichtigen:</span><span class="sxs-lookup"><span data-stu-id="9547a-191">Reasons for this include the following:</span></span>

- <span data-ttu-id="9547a-192">Das Abfangen von Ausnahmen zur Laufzeit sorgt für zusätzlichen mehr Aufwand und ist wahrscheinlich langsamer als die vorab Überprüfung, um Ausnahmen zu vermeiden.</span><span class="sxs-lookup"><span data-stu-id="9547a-192">Catching exceptions at runtime creates additional overhead, and is likely to be slower than pre-checking to avoid exceptions.</span></span>

- <span data-ttu-id="9547a-193">Wenn ein `Catch` Block nicht ordnungsgemäß behandelt wird, wird die Ausnahme möglicherweise nicht ordnungsgemäß für die Benutzer gemeldet.</span><span class="sxs-lookup"><span data-stu-id="9547a-193">If a `Catch` block is not handled correctly, the exception might not be reported correctly to users.</span></span>

- <span data-ttu-id="9547a-194">Durch die Ausnahmebehandlung wird ein Programm komplexer.</span><span class="sxs-lookup"><span data-stu-id="9547a-194">Exception handling makes a program more complex.</span></span>

<span data-ttu-id="9547a-195">Sie benötigen nicht immer eine- `Try…Catch` Anweisung, um eine Bedingung zu prüfen, die wahrscheinlich auftritt.</span><span class="sxs-lookup"><span data-stu-id="9547a-195">You do not always need a `Try…Catch` statement to check for a condition that is likely to occur.</span></span> <span data-ttu-id="9547a-196">Im folgenden Beispiel wird überprüft, ob eine Datei vorhanden ist, bevor versucht wird, Sie zu öffnen.</span><span class="sxs-lookup"><span data-stu-id="9547a-196">The following example checks whether a file exists before trying to open it.</span></span> <span data-ttu-id="9547a-197">Dies verringert die Notwendigkeit, eine von der-Methode ausgelöste Ausnahme abzufangen <xref:System.IO.File.OpenText%2A> .</span><span class="sxs-lookup"><span data-stu-id="9547a-197">This reduces the need for catching an exception thrown by the <xref:System.IO.File.OpenText%2A> method.</span></span>

[!code-vb[VbVbalrStatements#94](~/samples/snippets/visualbasic/VS_Snippets_VBCSharp/VbVbalrStatements/VB/Class1.vb#94)]

<span data-ttu-id="9547a-198">Stellen Sie sicher, dass Code in `Catch` Blöcken Ausnahmen für Benutzer ordnungsgemäß melden kann, egal ob durch Thread sichere Protokollierung oder entsprechende Nachrichten.</span><span class="sxs-lookup"><span data-stu-id="9547a-198">Ensure that code in `Catch` blocks can properly report exceptions to users, whether through thread-safe logging or appropriate messages.</span></span> <span data-ttu-id="9547a-199">Andernfalls können Ausnahmen unbekannt bleiben.</span><span class="sxs-lookup"><span data-stu-id="9547a-199">Otherwise, exceptions might remain unknown.</span></span>

## <a name="async-methods"></a><span data-ttu-id="9547a-200">Asynchrone Methoden</span><span class="sxs-lookup"><span data-stu-id="9547a-200">Async methods</span></span>

<span data-ttu-id="9547a-201">Wenn Sie eine Methode mit dem [Async](../modifiers/async.md) -Modifizierer markieren, können Sie den [Erwartungs Operator in](../operators/await-operator.md) der-Methode verwenden.</span><span class="sxs-lookup"><span data-stu-id="9547a-201">If you mark a method with the [Async](../modifiers/async.md) modifier, you can use the [Await](../operators/await-operator.md) operator in the method.</span></span> <span data-ttu-id="9547a-202">Eine-Anweisung mit dem-Operator hält die Ausführung der- `Await` Methode an, bis die erwartete Aufgabe abgeschlossen ist.</span><span class="sxs-lookup"><span data-stu-id="9547a-202">A statement with the `Await` operator suspends execution of the method until the awaited task completes.</span></span> <span data-ttu-id="9547a-203">Die Aufgabe stellt derzeit ausgeführte Arbeit dar.</span><span class="sxs-lookup"><span data-stu-id="9547a-203">The task represents ongoing work.</span></span> <span data-ttu-id="9547a-204">Wenn die dem Operator zugeordnete Aufgabe `Await` abgeschlossen ist, wird die Ausführung in derselben Methode fortgesetzt.</span><span class="sxs-lookup"><span data-stu-id="9547a-204">When the task that's associated with the `Await` operator finishes, execution resumes in the same method.</span></span> <span data-ttu-id="9547a-205">Weitere Informationen finden Sie unter [Ablauf Steuerung in Async-Programmen](../../programming-guide/concepts/async/control-flow-in-async-programs.md).</span><span class="sxs-lookup"><span data-stu-id="9547a-205">For more information, see [Control Flow in Async Programs](../../programming-guide/concepts/async/control-flow-in-async-programs.md).</span></span>

<span data-ttu-id="9547a-206">Eine Aufgabe, die von einer asynchronen Methode zurückgegeben wird, kann mit einem fehlerhaften Zustand enden, was darauf hinweist, dass Sie aufgrund einer nicht behandelten Ausnahme abgeschlossen wurde.</span><span class="sxs-lookup"><span data-stu-id="9547a-206">A task returned by an Async method may end in a faulted state, indicating that it completed due to an unhandled exception.</span></span> <span data-ttu-id="9547a-207">Eine Aufgabe kann auch in einem abgebrochenen Zustand enden, was dazu führt, `OperationCanceledException` dass aus dem Erwartungs Ausdruck ausgelöst wird.</span><span class="sxs-lookup"><span data-stu-id="9547a-207">A task may also end in a canceled state, which results in an `OperationCanceledException` being thrown out of the await expression.</span></span> <span data-ttu-id="9547a-208">Um einen der beiden Ausnahme Typen abzufangen, platzieren Sie den Ausdruck, der `Await` der Aufgabe zugeordnet ist, in einem `Try` -Block, und fangen Sie die Ausnahme im- `Catch` Block ab.</span><span class="sxs-lookup"><span data-stu-id="9547a-208">To catch either type of exception, place the `Await` expression that's associated with the task in a `Try` block, and catch the exception in the `Catch` block.</span></span> <span data-ttu-id="9547a-209">Ein Beispiel finden Sie weiter unten in diesem Thema.</span><span class="sxs-lookup"><span data-stu-id="9547a-209">An example is provided later in this topic.</span></span>

<span data-ttu-id="9547a-210">Eine Aufgabe kann sich in einem fehlerhaften Zustand befinden, da mehrere Ausnahmen für Ihren Fehler verantwortlich sind.</span><span class="sxs-lookup"><span data-stu-id="9547a-210">A task can be in a faulted state because multiple exceptions were responsible for its faulting.</span></span> <span data-ttu-id="9547a-211">Beispielsweise kann die Aufgabe das Ergebnis eines Aufrufs an <xref:System.Threading.Tasks.Task.WhenAll%2A?displayProperty=nameWithType> sein.</span><span class="sxs-lookup"><span data-stu-id="9547a-211">For example, the task might be the result of a call to <xref:System.Threading.Tasks.Task.WhenAll%2A?displayProperty=nameWithType>.</span></span> <span data-ttu-id="9547a-212">Wenn Sie auf eine solche Aufgabe warten, ist die abgefangene Ausnahme nur eine der Ausnahmen, und Sie können nicht vorhersagen, welche Ausnahme abgefangen wird.</span><span class="sxs-lookup"><span data-stu-id="9547a-212">When you await such a task, the caught exception is only one of the exceptions, and you can't predict which exception will be caught.</span></span> <span data-ttu-id="9547a-213">Ein Beispiel finden Sie weiter unten in diesem Thema.</span><span class="sxs-lookup"><span data-stu-id="9547a-213">An example is provided later in this topic.</span></span>

<span data-ttu-id="9547a-214">Ein `Await` Ausdruck darf sich nicht innerhalb eines `Catch` Blocks oder `Finally` Blocks befinden.</span><span class="sxs-lookup"><span data-stu-id="9547a-214">An `Await` expression can't be inside a `Catch` block or `Finally` block.</span></span>

## <a name="iterators"></a><span data-ttu-id="9547a-215">Iterators</span><span class="sxs-lookup"><span data-stu-id="9547a-215">Iterators</span></span>

<span data-ttu-id="9547a-216">Eine Iteratorfunktion oder ein- `Get` Accessor führt eine benutzerdefinierte Iterations Funktion für eine Auflistung aus.</span><span class="sxs-lookup"><span data-stu-id="9547a-216">An iterator function or `Get` accessor performs a custom iteration over a collection.</span></span> <span data-ttu-id="9547a-217">Ein Iterator verwendet eine [Yield](yield-statement.md) -Anweisung, um jedes Element der Auflistung einzeln zurückzugeben.</span><span class="sxs-lookup"><span data-stu-id="9547a-217">An iterator uses a [Yield](yield-statement.md) statement to return each element of the collection one at a time.</span></span> <span data-ttu-id="9547a-218">Sie stellen eine Iteratorfunktion mithilfe eines [for each-... Next-Anweisung](for-each-next-statement.md).</span><span class="sxs-lookup"><span data-stu-id="9547a-218">You call an iterator function by using a [For Each...Next Statement](for-each-next-statement.md).</span></span>

<span data-ttu-id="9547a-219">Eine- `Yield` Anweisung kann sich in einem- `Try` Block befinden.</span><span class="sxs-lookup"><span data-stu-id="9547a-219">A `Yield` statement can be inside a `Try` block.</span></span> <span data-ttu-id="9547a-220">Ein `Try` -Block, der eine `Yield` -Anweisung enthält `Catch` , kann-Blöcke aufweisen und kann einen-Block aufweisen `Finally` .</span><span class="sxs-lookup"><span data-stu-id="9547a-220">A `Try` block that contains a `Yield` statement can have `Catch` blocks, and can have a `Finally` block.</span></span> <span data-ttu-id="9547a-221">Ein Beispiel finden Sie im Abschnitt "try Blocks in Visual Basic" unter [Iteratoren](../../programming-guide/concepts/iterators.md) .</span><span class="sxs-lookup"><span data-stu-id="9547a-221">See the "Try Blocks in Visual Basic" section of [Iterators](../../programming-guide/concepts/iterators.md) for an example.</span></span>

<span data-ttu-id="9547a-222">Eine- `Yield` Anweisung darf sich nicht in einem- `Catch` Block oder einem- `Finally` Block befinden.</span><span class="sxs-lookup"><span data-stu-id="9547a-222">A `Yield` statement cannot be inside a `Catch` block or a `Finally` block.</span></span>

<span data-ttu-id="9547a-223">Wenn der `For Each` Text (außerhalb der Iteratorfunktion) eine Ausnahme auslöst, wird ein- `Catch` Block in der Iteratorfunktion nicht ausgeführt, aber ein- `Finally` Block in der Iteratorfunktion wird ausgeführt.</span><span class="sxs-lookup"><span data-stu-id="9547a-223">If the `For Each` body (outside of the iterator function) throws an exception, a `Catch` block in the iterator function is not executed, but a `Finally` block in the iterator function is executed.</span></span> <span data-ttu-id="9547a-224">Ein `Catch` Block in einer Iteratorfunktion fängt nur Ausnahmen ab, die innerhalb der Iteratorfunktion auftreten.</span><span class="sxs-lookup"><span data-stu-id="9547a-224">A `Catch` block inside an iterator function catches only exceptions that occur inside the iterator function.</span></span>

## <a name="partial-trust-situations"></a><span data-ttu-id="9547a-225">Teilweise vertrauenswürdige Situationen</span><span class="sxs-lookup"><span data-stu-id="9547a-225">Partial-trust situations</span></span>

<span data-ttu-id="9547a-226">In teilweise vertrauenswürdigen Situationen, z. b. eine Anwendung, die auf einer Netzwerkfreigabe gehostet wird, `Try...Catch...Finally` fängt keine Sicherheits Ausnahmen ab, die auftreten, bevor die Methode, die den Aufruf enthält, aufgerufen wird.</span><span class="sxs-lookup"><span data-stu-id="9547a-226">In partial-trust situations, such as an application hosted on a network share, `Try...Catch...Finally` does not catch security exceptions that occur before the method that contains the call is invoked.</span></span> <span data-ttu-id="9547a-227">Im folgenden Beispiel wird der Fehler "System. Security. SecurityException: Anforderungs Fehler" erzeugt, wenn Sie ihn auf einer Server Freigabe platzieren und dort ausführen.</span><span class="sxs-lookup"><span data-stu-id="9547a-227">The following example, when you put it on a server share and run from there, produces the error "System.Security.SecurityException: Request Failed."</span></span> <span data-ttu-id="9547a-228">Weitere Informationen zu Sicherheits Ausnahmen finden Sie unter der- <xref:System.Security.SecurityException> Klasse.</span><span class="sxs-lookup"><span data-stu-id="9547a-228">For more information about security exceptions, see the <xref:System.Security.SecurityException> class.</span></span>

[!code-vb[VbVbalrStatements#85](~/samples/snippets/visualbasic/VS_Snippets_VBCSharp/VbVbalrStatements/VB/Class1.vb#85)]

<span data-ttu-id="9547a-229">In solch einer teilweise vertrauenswürdigen Situation müssen Sie die `Process.Start` Anweisung in einen separaten einfügen `Sub` .</span><span class="sxs-lookup"><span data-stu-id="9547a-229">In such a partial-trust situation, you have to put the `Process.Start` statement in a separate `Sub`.</span></span> <span data-ttu-id="9547a-230">Der erste Rückruf von `Sub` schlägt fehl.</span><span class="sxs-lookup"><span data-stu-id="9547a-230">The initial call to the `Sub` will fail.</span></span> <span data-ttu-id="9547a-231">Dies ermöglicht das `Try...Catch` abfangen, bevor das `Sub` enthält, das enthält, `Process.Start` und die Sicherheits Ausnahme wird ausgelöst.</span><span class="sxs-lookup"><span data-stu-id="9547a-231">This enables `Try...Catch` to catch it before the `Sub` that contains `Process.Start` is started and the security exception produced.</span></span>

## <a name="examples"></a><span data-ttu-id="9547a-232">Beispiele</span><span class="sxs-lookup"><span data-stu-id="9547a-232">Examples</span></span>

### <a name="the-structure-of-trycatchfinally"></a><span data-ttu-id="9547a-233">Die Struktur von Try... Catch... Endlich</span><span class="sxs-lookup"><span data-stu-id="9547a-233">The structure of Try...Catch...Finally</span></span>

<span data-ttu-id="9547a-234">Das folgende Beispiel veranschaulicht die Struktur der- `Try...Catch...Finally` Anweisung.</span><span class="sxs-lookup"><span data-stu-id="9547a-234">The following example illustrates the structure of the `Try...Catch...Finally` statement.</span></span>

[!code-vb[VbVbalrStatements#86](~/samples/snippets/visualbasic/VS_Snippets_VBCSharp/VbVbalrStatements/VB/Class1.vb#86)]  

### <a name="exception-in-a-method-called-from-a-try-block"></a><span data-ttu-id="9547a-235">Ausnahme in einer Methode, die von einem try-Block aufgerufen wird.</span><span class="sxs-lookup"><span data-stu-id="9547a-235">Exception in a method called from a Try block</span></span>

<span data-ttu-id="9547a-236">Im folgenden Beispiel löst die- `CreateException` Methode eine aus `NullReferenceException` .</span><span class="sxs-lookup"><span data-stu-id="9547a-236">In the following example, the `CreateException` method throws a `NullReferenceException`.</span></span> <span data-ttu-id="9547a-237">Der Code, der die Ausnahme generiert, befindet sich nicht in einem- `Try` Block.</span><span class="sxs-lookup"><span data-stu-id="9547a-237">The code that generates the exception is not in a `Try` block.</span></span> <span data-ttu-id="9547a-238">Daher wird die Ausnahme von der- `CreateException` Methode nicht behandelt.</span><span class="sxs-lookup"><span data-stu-id="9547a-238">Therefore, the `CreateException` method does not handle the exception.</span></span> <span data-ttu-id="9547a-239">Die- `RunSample` Methode behandelt die Ausnahme, da sich der aufzurufende- `CreateException` Methode in einem- `Try` Block befindet.</span><span class="sxs-lookup"><span data-stu-id="9547a-239">The `RunSample` method does handle the exception because the call to the `CreateException` method is in a `Try` block.</span></span>

<span data-ttu-id="9547a-240">Das Beispiel enthält `Catch` Anweisungen für verschiedene Typen von Ausnahmen, die von der spezifischsten bis zur allgemeinsten geordnet sind.</span><span class="sxs-lookup"><span data-stu-id="9547a-240">The example includes `Catch` statements for several types of exceptions, ordered from the most specific to the most general.</span></span>

[!code-vb[VbVbalrStatements#91](~/samples/snippets/visualbasic/VS_Snippets_VBCSharp/VbVbalrStatements/VB/Class1.vb#91)]

### <a name="the-catch-when-statement"></a><span data-ttu-id="9547a-241">Die Catch When-Anweisung</span><span class="sxs-lookup"><span data-stu-id="9547a-241">The Catch When statement</span></span>

<span data-ttu-id="9547a-242">Im folgenden Beispiel wird gezeigt, wie eine-Anweisung verwendet wird `Catch When` , um nach einem bedingten Ausdruck zu filtern.</span><span class="sxs-lookup"><span data-stu-id="9547a-242">The following example shows how to use a `Catch When` statement to filter on a conditional expression.</span></span> <span data-ttu-id="9547a-243">Wenn der bedingte Ausdruck ergibt `True` , wird der Code im- `Catch` Block ausgeführt.</span><span class="sxs-lookup"><span data-stu-id="9547a-243">If the conditional expression evaluates to `True`, the code in the `Catch` block runs.</span></span>

[!code-vb[VbVbalrStatements#92](~/samples/snippets/visualbasic/VS_Snippets_VBCSharp/VbVbalrStatements/VB/Class1.vb#92)]

### <a name="nested-try-statements"></a><span data-ttu-id="9547a-244">T-Anweisungen in der Liste</span><span class="sxs-lookup"><span data-stu-id="9547a-244">Nested Try statements</span></span>

<span data-ttu-id="9547a-245">Das folgende Beispiel enthält eine- `Try…Catch` Anweisung, die in einem-Block enthalten ist `Try` .</span><span class="sxs-lookup"><span data-stu-id="9547a-245">The following example has a `Try…Catch` statement that is contained in a `Try` block.</span></span> <span data-ttu-id="9547a-246">Der innere- `Catch` Block löst eine Ausnahme aus, bei der die- `InnerException` Eigenschaft auf die ursprüngliche Ausnahme festgelegt ist.</span><span class="sxs-lookup"><span data-stu-id="9547a-246">The inner `Catch` block throws an exception that has its `InnerException` property set to the original exception.</span></span> <span data-ttu-id="9547a-247">Der äußere `Catch` Block meldet seine eigene Ausnahme und die innere Ausnahme.</span><span class="sxs-lookup"><span data-stu-id="9547a-247">The outer `Catch` block reports its own exception and the inner exception.</span></span>

[!code-vb[VbVbalrStatements#93](~/samples/snippets/visualbasic/VS_Snippets_VBCSharp/VbVbalrStatements/VB/Class1.vb#93)]

### <a name="exception-handling-for-async-methods"></a><span data-ttu-id="9547a-248">Ausnahmebehandlung für Async-Methoden</span><span class="sxs-lookup"><span data-stu-id="9547a-248">Exception handling for async methods</span></span>

<span data-ttu-id="9547a-249">Im folgenden Beispiel wird die Ausnahmebehandlung für asynchrone Methoden veranschaulicht.</span><span class="sxs-lookup"><span data-stu-id="9547a-249">The following example illustrates exception handling for async methods.</span></span> <span data-ttu-id="9547a-250">Zum Abfangen einer Ausnahme, die für eine Async-Aufgabe gilt, befindet sich der `Await` Ausdruck in einem `Try` Block des Aufrufers, und die Ausnahme wird im- `Catch` Block abgefangen.</span><span class="sxs-lookup"><span data-stu-id="9547a-250">To catch an exception that applies to an async task, the `Await` expression is in a `Try` block of the caller, and the exception is caught in the `Catch` block.</span></span>

<span data-ttu-id="9547a-251">Heben Sie die Auskommentierung der Zeile `Throw New Exception` im Beispiel auf, um die Ausnahmebehandlung zu veranschaulichen.</span><span class="sxs-lookup"><span data-stu-id="9547a-251">Uncomment the `Throw New Exception` line in the example to demonstrate exception handling.</span></span> <span data-ttu-id="9547a-252">Die Ausnahme wird im- `Catch` Block abgefangen, die-Eigenschaft der Aufgabe `IsFaulted` wird auf festgelegt `True` , und die-Eigenschaft der Aufgabe `Exception.InnerException` wird auf die-Ausnahme festgelegt.</span><span class="sxs-lookup"><span data-stu-id="9547a-252">The exception is caught in the `Catch` block, the task's `IsFaulted` property is set to `True`, and the task's `Exception.InnerException` property is set to the exception.</span></span>

<span data-ttu-id="9547a-253">Heben Sie die Auskommentierung der Zeile `Throw New OperationCancelledException` auf, um zu veranschaulichen, was beim Abbrechen eines asynchronen Prozesses passiert.</span><span class="sxs-lookup"><span data-stu-id="9547a-253">Uncomment the `Throw New OperationCancelledException` line to demonstrate what happens when you cancel an asynchronous process.</span></span> <span data-ttu-id="9547a-254">Die Ausnahme wird im `Catch` -Block abgefangen, und die-Eigenschaft der Aufgabe `IsCanceled` wird auf festgelegt `True` .</span><span class="sxs-lookup"><span data-stu-id="9547a-254">The exception is caught in the `Catch` block, and the task's `IsCanceled` property is set to `True`.</span></span> <span data-ttu-id="9547a-255">Unter bestimmten Bedingungen, die für dieses Beispiel nicht gelten, `IsFaulted` wird jedoch auf festgelegt, `True` und `IsCanceled` ist auf festgelegt `False` .</span><span class="sxs-lookup"><span data-stu-id="9547a-255">However, under some conditions that don't apply to this example, `IsFaulted` is set to `True` and `IsCanceled` is set to `False`.</span></span>

[!code-vb[csAsyncExceptions#1](~/samples/snippets/visualbasic/VS_Snippets_VBCSharp/csasyncexceptions/vb/class1.vb#1)]

### <a name="handling-multiple-exceptions-in-async-methods"></a><span data-ttu-id="9547a-256">Behandeln mehrerer Ausnahmen in Async-Methoden</span><span class="sxs-lookup"><span data-stu-id="9547a-256">Handling multiple exceptions in async methods</span></span>

<span data-ttu-id="9547a-257">Das folgende Beispiel veranschaulicht die Behandlung von Ausnahmen in Fällen, in denen mehrere Aufgaben zu mehreren Ausnahmen führen können.</span><span class="sxs-lookup"><span data-stu-id="9547a-257">The following example illustrates exception handling where multiple tasks can result in multiple exceptions.</span></span> <span data-ttu-id="9547a-258">Der- `Try` Block enthält den `Await` Ausdruck für die Aufgabe, die <xref:System.Threading.Tasks.Task.WhenAll%2A?displayProperty=nameWithType> zurückgegeben hat.</span><span class="sxs-lookup"><span data-stu-id="9547a-258">The `Try` block has the `Await` expression for the task that <xref:System.Threading.Tasks.Task.WhenAll%2A?displayProperty=nameWithType> returned.</span></span> <span data-ttu-id="9547a-259">Die Aufgabe ist fertiggestellt, wenn die drei Aufgaben, auf die <xref:System.Threading.Tasks.Task.WhenAll%2A?displayProperty=nameWithType> angewendet wird, fertiggestellt sind.</span><span class="sxs-lookup"><span data-stu-id="9547a-259">The task is complete when the three tasks to which <xref:System.Threading.Tasks.Task.WhenAll%2A?displayProperty=nameWithType> is applied are complete.</span></span>

<span data-ttu-id="9547a-260">Jede der drei Aufgaben löst eine Ausnahme aus.</span><span class="sxs-lookup"><span data-stu-id="9547a-260">Each of the three tasks causes an exception.</span></span> <span data-ttu-id="9547a-261">Der- `Catch` Block durchläuft die Ausnahmen, die in der- `Exception.InnerExceptions` Eigenschaft der Aufgabe, die zurückgegeben hat, gefunden werden `Task.WhenAll` .</span><span class="sxs-lookup"><span data-stu-id="9547a-261">The `Catch` block iterates through the exceptions, which are found in the `Exception.InnerExceptions` property of the task that `Task.WhenAll` returned.</span></span>

[!code-vb[csAsyncExceptions#3](~/samples/snippets/visualbasic/VS_Snippets_VBCSharp/csasyncexceptions/vb/class1.vb#3)]

## <a name="see-also"></a><span data-ttu-id="9547a-262">Weitere Informationen</span><span class="sxs-lookup"><span data-stu-id="9547a-262">See also</span></span>

- <xref:Microsoft.VisualBasic.Information.Err%2A>
- <xref:System.Exception>
- [<span data-ttu-id="9547a-263">Exit-Anweisung</span><span class="sxs-lookup"><span data-stu-id="9547a-263">Exit Statement</span></span>](exit-statement.md)
- [<span data-ttu-id="9547a-264">On Error-Anweisung</span><span class="sxs-lookup"><span data-stu-id="9547a-264">On Error Statement</span></span>](on-error-statement.md)
- [<span data-ttu-id="9547a-265">Empfohlene Vorgehensweisen für die Verwendung von Codeausschnitten</span><span class="sxs-lookup"><span data-stu-id="9547a-265">Best Practices for Using Code Snippets</span></span>](/visualstudio/ide/best-practices-for-using-code-snippets)
- [<span data-ttu-id="9547a-266">Ausnahmebehandlung</span><span class="sxs-lookup"><span data-stu-id="9547a-266">Exception Handling</span></span>](../../../standard/parallel-programming/exception-handling-task-parallel-library.md)
- [<span data-ttu-id="9547a-267">Throw-Anweisung</span><span class="sxs-lookup"><span data-stu-id="9547a-267">Throw Statement</span></span>](throw-statement.md)
