---
title: "\"Catch\" kann nicht außerhalb einer Try-Anweisung verwendet werden"
ms.date: 07/20/2015
f1_keywords:
- bc30380
- vbc30380
helpviewer_keywords:
- BC30380
ms.assetid: 73ce950d-881f-4532-8024-40a4930abd32
ms.openlocfilehash: c8e2b8f9ea5bf5165a97c5b38261a79df1e3b894
ms.sourcegitcommit: f8c270376ed905f6a8896ce0fe25b4f4b38ff498
ms.translationtype: MT
ms.contentlocale: de-DE
ms.lasthandoff: 06/04/2020
ms.locfileid: "84403757"
---
# <a name="catch-cannot-appear-outside-a-try-statement"></a>"Catch" kann nicht außerhalb einer Try-Anweisung verwendet werden
`Catch` muss innerhalb eines `Try...Catch...Finally` -Anweisungsblocks angezeigt werden. Entweder ist die `Catch` -Anweisung im `Try` -Block unnötig, oder die `Catch` -Anweisung befindet sich außerhalb des entsprechenden `Try` -Blocks.  
  
 **Fehler-ID:** BC30380  
  
## <a name="to-correct-this-error"></a>So beheben Sie diesen Fehler  
  
1. Löschen Sie die `Catch` -Anweisung, wenn sie unnötig ist, oder platzieren Sie sie in einem `Try...Catch...Finally` -Anweisungsblock.  
  
## <a name="see-also"></a>Weitere Informationen

- [Try...Catch...Finally-Anweisung](../language-reference/statements/try-catch-finally-statement.md)
