---
title: Verwenden von Ausnahmen – C#-Programmierhandbuch
ms.date: 07/20/2015
helpviewer_keywords:
- exception handling [C#], about exception handling
- exceptions [C#], about exceptions
ms.assetid: 71472c62-320a-470a-97d2-67995180389d
ms.openlocfilehash: a00259dfd5634ad9b9c951c3cd76da97afe5077d
ms.sourcegitcommit: a241301495a84cc8c64fe972330d16edd619868b
ms.translationtype: HT
ms.contentlocale: de-DE
ms.lasthandoff: 06/01/2020
ms.locfileid: "84241694"
---
# <a name="use-exceptions-c-programming-guide"></a><span data-ttu-id="1ffc2-102">Verwenden von Ausnahmen (C#-Programmierhandbuch)</span><span class="sxs-lookup"><span data-stu-id="1ffc2-102">Use exceptions (C# programming guide)</span></span>

<span data-ttu-id="1ffc2-103">In C# werden Fehler im Programm zur Laufzeit mithilfe von sogenannten Ausnahmen durch das Programm weitergegeben.</span><span class="sxs-lookup"><span data-stu-id="1ffc2-103">In C#, errors in the program at run time are propagated through the program by using a mechanism called exceptions.</span></span> <span data-ttu-id="1ffc2-104">Ausnahmen werden von Code ausgelöst, der auf einen Fehler stößt. Sie werden von Code abgefangen, der den Fehler beheben kann.</span><span class="sxs-lookup"><span data-stu-id="1ffc2-104">Exceptions are thrown by code that encounters an error and caught by code that can correct the error.</span></span> <span data-ttu-id="1ffc2-105">Ausnahmen können durch die .NET-Runtime oder durch Code in einem Programm ausgelöst werden.</span><span class="sxs-lookup"><span data-stu-id="1ffc2-105">Exceptions can be thrown by the .NET runtime or by code in a program.</span></span> <span data-ttu-id="1ffc2-106">Sobald eine Ausnahme ausgelöst wird, wird sie in der Aufrufliste nach oben weitergegeben, bis eine `catch`-Anweisung für die Ausnahme gefunden wird.</span><span class="sxs-lookup"><span data-stu-id="1ffc2-106">Once an exception is thrown, it propagates up the call stack until a `catch` statement for the exception is found.</span></span> <span data-ttu-id="1ffc2-107">Nicht abgefangene Ausnahmen werden von einem generischen Ausnahmehandler behandelt, der vom System bereitgestellt wird, das ein Dialogfeld anzeigt.</span><span class="sxs-lookup"><span data-stu-id="1ffc2-107">Uncaught exceptions are handled by a generic exception handler provided by the system that displays a dialog box.</span></span>  
  
 <span data-ttu-id="1ffc2-108">Ausnahmen werden von Klassen dargestellt, die von <xref:System.Exception> abgeleitet sind.</span><span class="sxs-lookup"><span data-stu-id="1ffc2-108">Exceptions are represented by classes derived from <xref:System.Exception>.</span></span> <span data-ttu-id="1ffc2-109">Diese Klasse bestimmt den Typ der Ausnahme und enthält Eigenschaften, die über Details zur Ausnahme verfügen.</span><span class="sxs-lookup"><span data-stu-id="1ffc2-109">This class identifies the type of exception and contains properties that have details about the exception.</span></span> <span data-ttu-id="1ffc2-110">Das Auslösen einer Ausnahme umfasst das Erstellen einer Instanz einer von einer Ausnahme abgeleiteten Klasse, das optionale Konfigurieren von Eigenschaften der Ausnahme und das Auslösen des Objekts mithilfe des Schlüsselworts `throw`.</span><span class="sxs-lookup"><span data-stu-id="1ffc2-110">Throwing an exception involves creating an instance of an exception-derived class, optionally configuring properties of the exception, and then throwing the object by using the `throw` keyword.</span></span> <span data-ttu-id="1ffc2-111">Zum Beispiel:</span><span class="sxs-lookup"><span data-stu-id="1ffc2-111">For example:</span></span>  
  
 [!code-csharp[csProgGuideExceptions#1](~/samples/snippets/csharp/VS_Snippets_VBCSharp/csProgGuideExceptions/CS/Exceptions.cs#1)]  
  
 <span data-ttu-id="1ffc2-112">Nachdem eine Ausnahme ausgelöst wird, überprüft die Runtime die aktuelle Anweisung, um festzustellen, ob sie sich in einem `try`-Block befindet.</span><span class="sxs-lookup"><span data-stu-id="1ffc2-112">After an exception is thrown, the runtime checks the current statement to see whether it is within a `try` block.</span></span> <span data-ttu-id="1ffc2-113">Falls dies der Fall ist, werden alle mit dem `try`-Block verknüpften `catch`-Blöcke überprüft, um festzustellen, ob sie die Ausnahme abfangen können.</span><span class="sxs-lookup"><span data-stu-id="1ffc2-113">If it is, any `catch` blocks associated with the `try` block are checked to see whether they can catch the exception.</span></span> <span data-ttu-id="1ffc2-114">`Catch`-Blöcke geben normalerweise Ausnahmetypen an; wenn der Typ des `catch`-Blocks der gleiche Typ ist wie die Ausnahme oder die Basisklasse der Ausnahme, kann der `catch`-Block die Methode behandeln.</span><span class="sxs-lookup"><span data-stu-id="1ffc2-114">`Catch` blocks typically specify exception types; if the type of the `catch` block is the same type as the exception, or a base class of the exception, the `catch` block can handle the method.</span></span> <span data-ttu-id="1ffc2-115">Zum Beispiel:</span><span class="sxs-lookup"><span data-stu-id="1ffc2-115">For example:</span></span>  
  
 [!code-csharp[csProgGuideExceptions#2](~/samples/snippets/csharp/VS_Snippets_VBCSharp/csProgGuideExceptions/CS/Exceptions.cs#2)]  
  
 <span data-ttu-id="1ffc2-116">Wenn sich die Anweisung, die eine Ausnahme auslöst, nicht innerhalb eines `try`-Blocks befindet, oder der `try`-Block, der sie umfasst, über keinen übereinstimmenden `catch`-Block verfügt, überprüft die Runtime die aufrufende Methode auf eine `try`-Anweisung und `catch`-Blöcke.</span><span class="sxs-lookup"><span data-stu-id="1ffc2-116">If the statement that throws an exception is not within a `try` block or if the `try` block that encloses it has no matching `catch` block, the runtime checks the calling method for a `try` statement and `catch` blocks.</span></span> <span data-ttu-id="1ffc2-117">Die Runtime geht die Aufrufliste weiter nach oben durch und sucht nach einem kompatiblen `catch`-Block.</span><span class="sxs-lookup"><span data-stu-id="1ffc2-117">The runtime continues up the calling stack, searching for a compatible `catch` block.</span></span> <span data-ttu-id="1ffc2-118">Nachdem der `catch`-Block gefunden und ausgeführt wurde, wird die Steuerung an die nächste Anweisung nach diesem `catch`-Block weitergegeben.</span><span class="sxs-lookup"><span data-stu-id="1ffc2-118">After the `catch` block is found and executed, control is passed to the next statement after that `catch` block.</span></span>  
  
 <span data-ttu-id="1ffc2-119">Eine `try`-Anweisung kann mehr als einen `catch`-Block enthalten.</span><span class="sxs-lookup"><span data-stu-id="1ffc2-119">A `try` statement can contain more than one `catch` block.</span></span> <span data-ttu-id="1ffc2-120">Die erste `catch`-Anweisung, die die Ausnahme behandelt, wird ausgeführt; alle folgenden `catch`-Anweisungen werden ignoriert, selbst wenn sie kompatibel sind.</span><span class="sxs-lookup"><span data-stu-id="1ffc2-120">The first `catch` statement that can handle the exception is executed; any following `catch` statements, even if they are compatible, are ignored.</span></span> <span data-ttu-id="1ffc2-121">Daher sollten catch-Blöcke immer vom spezifischsten Element (oder am meisten abgeleiteten) zum am wenigsten spezifischen sortiert werden.</span><span class="sxs-lookup"><span data-stu-id="1ffc2-121">Therefore, catch blocks should always be ordered from most specific (or most-derived) to least specific.</span></span> <span data-ttu-id="1ffc2-122">Zum Beispiel:</span><span class="sxs-lookup"><span data-stu-id="1ffc2-122">For example:</span></span>  
  
 [!code-csharp[csProgGuideExceptions#3](~/samples/snippets/csharp/VS_Snippets_VBCSharp/csProgGuideExceptions/CS/Exceptions.cs#3)]  
  
 <span data-ttu-id="1ffc2-123">Bevor der `catch`-Block ausgeführt wird prüft die Runtime auf `finally`-Blöcke.</span><span class="sxs-lookup"><span data-stu-id="1ffc2-123">Before the `catch` block is executed, the runtime checks for `finally` blocks.</span></span> <span data-ttu-id="1ffc2-124">`Finally`-Blöcke ermöglichen dem Programmierer, mehrdeutige Zustände zu bereinigen, die möglicherweise von einem abgebrochenen `try`-Block übrig sind, oder externe Ressourcen freizugeben (z.B. Grafikhandles, Datenbankverbindungen oder Dateistreams), ohne auf Garbage Collector in der Runtime zum Finalisieren der Objekte zu warten.</span><span class="sxs-lookup"><span data-stu-id="1ffc2-124">`Finally` blocks enable the programmer to clean up any ambiguous state that could be left over from an aborted `try` block, or to release any external resources (such as graphics handles, database connections or file streams) without waiting for the garbage collector in the runtime to finalize the objects.</span></span> <span data-ttu-id="1ffc2-125">Zum Beispiel:</span><span class="sxs-lookup"><span data-stu-id="1ffc2-125">For example:</span></span>  
  
 [!code-csharp[csProgGuideExceptions#4](~/samples/snippets/csharp/VS_Snippets_VBCSharp/csProgGuideExceptions/CS/Exceptions.cs#4)]  
  
 <span data-ttu-id="1ffc2-126">Wenn `WriteByte()` eine Ausnahme auslöst, schlägt der Code im zweiten `try`-Block fehl, der versucht, die Datei erneut zu öffnen, wenn `file.Close()` nicht aufgerufen wird. Die Datei bleibt gesperrt.</span><span class="sxs-lookup"><span data-stu-id="1ffc2-126">If `WriteByte()` threw an exception, the code in the second `try` block that tries to reopen the file would fail if `file.Close()` is not called, and the file would remain locked.</span></span> <span data-ttu-id="1ffc2-127">Da `finally`-Blocke ausgeführt werden, selbst wenn eine Ausnahme ausgelöst wird, ermöglicht es der `finally`-Block im vorherigen Beispiel, dass die Datei korrekt geschlossen wird und trägt so zur Fehlervermeidung bei.</span><span class="sxs-lookup"><span data-stu-id="1ffc2-127">Because `finally` blocks are executed even if an exception is thrown, the `finally` block in the previous example allows for the file to be closed correctly and helps avoid an error.</span></span>  
  
 <span data-ttu-id="1ffc2-128">Wenn in der Aufrufliste kein kompatibler `catch`-Block gefunden wird, nachdem eine Ausnahme ausgelöst wird, tritt eine der folgenden Situationen auf:</span><span class="sxs-lookup"><span data-stu-id="1ffc2-128">If no compatible `catch` block is found on the call stack after an exception is thrown, one of three things occurs:</span></span>  
  
- <span data-ttu-id="1ffc2-129">Wenn die Ausnahme sich in einem Finalizer befindet, wird der Finalizer abgebrochen und der Basisfinalizer (sofern vorhanden) aufgerufen.</span><span class="sxs-lookup"><span data-stu-id="1ffc2-129">If the exception is within a finalizer, the finalizer is aborted and the base finalizer, if any, is called.</span></span>  
  
- <span data-ttu-id="1ffc2-130">Wenn die Aufrufliste einen statischen Konstruktor oder einen statischen Feldinitialisierer enthält, wird <xref:System.TypeInitializationException> ausgelöst und die ursprüngliche Ausnahme der <xref:System.Exception.InnerException%2A>-Eigenschaft der neuen Ausnahme zugewiesen.</span><span class="sxs-lookup"><span data-stu-id="1ffc2-130">If the call stack contains a static constructor, or a static field initializer, a <xref:System.TypeInitializationException> is thrown, with the original exception assigned to the <xref:System.Exception.InnerException%2A> property of the new exception.</span></span>  
  
- <span data-ttu-id="1ffc2-131">Wenn der Anfang des Threads erreicht wird, wird der Thread beendet.</span><span class="sxs-lookup"><span data-stu-id="1ffc2-131">If the start of the thread is reached, the thread is terminated.</span></span>  
  
## <a name="see-also"></a><span data-ttu-id="1ffc2-132">Siehe auch</span><span class="sxs-lookup"><span data-stu-id="1ffc2-132">See also</span></span>

- [<span data-ttu-id="1ffc2-133">C#-Programmierhandbuch</span><span class="sxs-lookup"><span data-stu-id="1ffc2-133">C# Programming Guide</span></span>](../index.md)
- [<span data-ttu-id="1ffc2-134">Ausnahmen und Ausnahmebehandlung</span><span class="sxs-lookup"><span data-stu-id="1ffc2-134">Exceptions and Exception Handling</span></span>](./index.md)
